Workbook

Sheet Palancas
A1: Aumentar venta | B1: Disminuir venta
A2: Oportunidades SEO | B2: Disminuir inversión en ads
A3: Oportunidades imágenes | B3: Sacar/ Modificar AON | P3: Busqueda
A4: Oportunidad clip | B4: Sacar/ Modificar DOD/Relámpago | Q4: Oportunidades SEO
A5: Republicar por mala experiencia/reseñas | Q5: Oportunidades imágenes/Clips
A6: Profundizar DOD | Q6: Republicar por mala experiencia/reseñas
A7: Aplicar descuentos mayoristas
A8: Aplicar Relámpago
A9: Subir el gasto en publicidad
A10: Profundizar AON
A11: Aplicar CMR
A12: Oportunidades logísticas (FULL, FLEX)
A13: Oportunidad ficha técnica
A14: Mayoristas
A15: Imagenes con AI
A18: Venta | B18: Impresiones | C18: CTR | D18: CVR
B19: SEO | C19: Imagen de portada | D19: SEO
B20: Metodos logisticos | D20: Fotos
B21: Reseñas | D21: Promesa de envio
B22: Historial de venta | D22: reseñas
B23: Categorizacion | D23: preguntas
B24: Ads | D24: etc
B28: ancho cm | C28: largo cm | D28: alto cm | E28: peso kg
A29: BANCOGYM001 | B29: 33 | C29: 81 | D29: 21 | E29: 12.6
A30: BATERIAELE001 | B30: 46 | C30: 77 | D30: 32 | E30: 19
A31: BICE003 | B31: 18 | C31: 82 | D31: 66 | E31: 17.1
A32: BICE004 | B32: 19 | C32: 90 | D32: 75 | E32: 22.1
A33: BICE005MAGNETIC | B33: 18 | C33: 92 | D33: 77 | E33: 24.3
A34: FRAZADAKING003AZUL | B34: 14 | C34: 35 | D34: 42 | E34: 1.75
A35: FRAZADAKING003GRIS | B35: 14 | C35: 35 | D35: 42 | E35: 1.68
A36: FRAZADAQUEEN004AZUL | B36: 11 | C36: 36 | D36: 43 | E36: 1.5
A37: FRAZADAQUEEN004GRIS | B37: 11 | C37: 36 | D37: 43 | E37: 1.5
A38: MONCURGAMER27 | B38: 13 | C38: 68 | D38: 44 | E38: 4.8
A39: MONCURGAMER34 | B39: 19 | C39: 98 | D39: 50 | E39: 7.8
A40: TROTAELEC002
A41: TROTAELEC003 | B41: 14 | C41: 126 | D41: 50.7 | E41: 20.4

Sheet Intro - Productos 2026
A1: SKU | B1: Maestro producto | C1: MELI | D1: Cuena de titulo | E1: CATALOGO | F1: FALA | G1: Cantidad de caracteres | H1: PREICO FULL | I1: % | J1: AON | K1: % | L1: DOD | M1: % | N1: Categoria a publicar | O1: Descripcion | P1: Velocidad Semanal Inicial | Q1: Mes Inicial | R1: Velocidad Semanal Madura | S1: Mes maduro | T1: Mes desarrollo | U1: variacion % FULL-AON | V1: variacion% AON-DOD | W1: Ancho / cm | X1: Largo / cm | Y1: Alto / cm | Z1: Peso | AA1: Comentarios | AB1: CBM Unitario
A2: FUNGUI002 | B2: - | C2: - | D2: =LEN(C2) -> 1 | E2: - | F2: - | G2: - | H2: 22990 | I2: 39.3 | J2: 18990 | K2: 43.3 | L2: 16990 | M2: 38.4 | N2: - | O2: - | P2: - | Q2: - | R2: - | S2: - | T2: - | U2: =1-(J2/H2) -> 0.17398869 | V2: =1-(L2/J2) -> 0.10531859 | W2: - | X2: - | Y2: - | Z2: - | AB2: =W2*X2*Y2/1000000 -> #VALUE!
A3: MOCHBOMBA001 | B3: - | C3: - | D3: =LEN(C3) -> 1 | E3: - | F3: - | G3: - | H3: 79990 | I3: 41.7 | J3: 69990 | K3: 35.5 | L3: 64990 | M3: 31.7 | N3: - | O3: - | P3: - | Q3: - | R3: - | S3: - | T3: - | U3: =1-(J3/H3) -> 0.12501563 | V3: =1-(L3/J3) -> 0.071438777 | W3: - | X3: - | Y3: - | Z3: - | AB3: =W3*X3*Y3/1000000 -> #VALUE!
A4: MOCHBOMBA002 | B4: - | C4: - | D4: =LEN(C4) -> 1 | E4: - | F4: - | G4: - | H4: 79990 | I4: 39.7 | J4: 69990 | K4: 33.2 | L4: 64990 | M4: 29.2 | N4: - | O4: - | P4: - | Q4: - | R4: - | S4: - | T4: - | U4: =1-(J4/H4) -> 0.12501563 | V4: =1-(L4/J4) -> 0.071438777 | W4: - | X4: - | Y4: - | Z4: - | AB4: =W4*X4*Y4/1000000 -> #VALUE!
A5: MOCHBOMBA003 | B5: - | C5: - | D5: =LEN(C5) -> 1 | E5: - | F5: - | G5: - | H5: 69990 | I5: 39.2 | J5: 64990 | K5: 35.6 | L5: 59990 | M5: 31.5 | N5: - | O5: - | P5: - | Q5: - | R5: - | S5: - | T5: - | U5: =1-(J5/H5) -> 0.071438777 | V5: =1-(L5/J5) -> 0.076934913 | W5: - | X5: - | Y5: - | Z5: - | AB5: =W5*X5*Y5/1000000 -> #VALUE!
A6: MOCHVIAJE010 | B6: - | C6: - | D6: =LEN(C6) -> 1 | E6: - | F6: - | G6: - | H6: 49990 | I6: 43.5 | J6: 44990 | K6: 38.9 | L6: 39990 | M6: 33.1 | N6: - | O6: - | P6: - | Q6: - | R6: - | S6: - | T6: - | U6: =1-(J6/H6) -> 0.10002 | V6: =1-(L6/J6) -> 0.11113581 | W6: - | X6: - | Y6: - | Z6: - | AB6: =W6*X6*Y6/1000000 -> #VALUE!
A7: MOCHVIAJE011 | B7: - | C7: - | D7: =LEN(C7) -> 1 | E7: - | F7: - | G7: - | H7: 44990 | I7: 60.6 | J7: 39990 | K7: 47.9 | L7: 34990 | M7: 42.6 | N7: - | O7: - | P7: - | Q7: - | R7: - | S7: - | T7: - | U7: =1-(J7/H7) -> 0.11113581 | V7: =1-(L7/J7) -> 0.12503126 | W7: - | X7: - | Y7: - | Z7: - | AB7: =W7*X7*Y7/1000000 -> #VALUE!
A8: BICE003 | B8: - | C8: - | D8: =LEN(C8) -> 1 | E8: - | F8: - | G8: - | H8: 129990 | I8: 35.8 | J8: 119990 | K8: 31.7 | L8: 109990 | M8: 26.9 | N8: - | O8: - | P8: - | Q8: - | R8: - | S8: - | T8: - | U8: =1-(J8/H8) -> 0.076928995 | V8: =1-(L8/J8) -> 0.083340278 | W8: - | X8: - | Y8: - | Z8: - | AB8: =W8*X8*Y8/1000000 -> #VALUE!
A9: BICE004 | B9: - | C9: - | D9: =LEN(C9) -> 1 | E9: - | F9: - | G9: - | H9: 169990 | I9: 37.5 | J9: 159990 | K9: 34.5 | L9: 149990 | M9: 31.1 | N9: - | O9: - | P9: - | Q9: - | R9: - | S9: - | T9: - | U9: =1-(J9/H9) -> 0.05882699 | V9: =1-(L9/J9) -> 0.062503906 | W9: - | X9: - | Y9: - | Z9: - | AB9: =W9*X9*Y9/1000000 -> #VALUE!
A10: BICE005MAGNETIC | B10: - | C10: - | D10: =LEN(C10) -> 1 | E10: - | F10: - | G10: - | H10: 199990 | I10: 39.7 | J10: 179990 | K10: 34.6 | L10: 169990 | M10: 31.7 | N10: - | O10: - | P10: - | Q10: - | R10: - | S10: - | T10: - | U10: =1-(J10/H10) -> 0.100005 | V10: =1-(L10/J10) -> 0.055558642 | W10: - | X10: - | Y10: - | Z10: - | AB10: =W10*X10*Y10/1000000 -> #VALUE!
A11: FRAZADAKING003AZUL | B11: - | C11: Frazada King Polar 300gsm Homely 250x230 Cm Azul Manta Lisa | D11: =LEN(C11) -> 59 | E11: Frazada King Polar 300gsm Homely 250x230 Cm Azul Manta Lisa Super Suave | F11: - | G11: - | H11: 39990 | I11: 56.1 | J11: 29990 | K11: 46.5 | L11: 24990 | M11: 33.8 | N11: - | O11: - | P11: - | Q11: - | R11: - | S11: - | T11: - | U11: =1-(J11/H11) -> 0.25006252 | V11: =1-(L11/J11) -> 0.16672224 | W11: - | X11: - | Y11: - | Z11: - | AB11: =W11*X11*Y11/1000000 -> #VALUE!
A12: FRAZADAKING003GRIS | B12: - | C12: Frazada King Polar 300gsm Homely 250x230 Cm Gris Manta Lisa | D12: =LEN(C12) -> 59 | E12: Frazada King Polar 300gsm Homely 250x230 Cm Gris Manta Lisa Super Suave | F12: - | G12: - | H12: 39990 | I12: 56.1 | J12: 29990 | K12: 46.5 | L12: 24990 | M12: 33.8 | N12: - | O12: - | P12: - | Q12: - | R12: - | S12: - | T12: - | U12: =1-(J12/H12) -> 0.25006252 | V12: =1-(L12/J12) -> 0.16672224 | W12: - | X12: - | Y12: - | Z12: - | AB12: =W12*X12*Y12/1000000 -> #VALUE!
A13: FRAZADAQUEEN004AZUL | B13: - | C13: Frazada 2 Plazas Polar 300gsm Homely 220x220 Cm Azul Queen | D13: =LEN(C13) -> 58 | E13: Frazada 2 Plazas Polar 300gsm Homely 220x220 Cm Azul Manta Lisa Queen Super Suave | F13: - | G13: - | H13: 24990 | I13: 42.3 | J13: 18990 | K13: 42.5 | L13: 16990 | M13: 37.4 | N13: - | O13: - | P13: - | Q13: - | R13: - | S13: - | T13: - | U13: =1-(J13/H13) -> 0.24009604 | V13: =1-(L13/J13) -> 0.10531859 | W13: - | X13: - | Y13: - | Z13: - | AB13: =W13*X13*Y13/1000000 -> #VALUE!
... A15: COLCHONETALIS002NEG | B15: - | C15: - | D15: =LEN(C15) -> 1 | E15: - | F15: - | G15: - | H15: 18990 | I15: 42.2 | J15: 16990 | K15: 37.2 | L15: 14990 | M15: 30.8 | N15: - | O15: - | P15: - | Q15: - | R15: - | S15: - | T15: - | U15: =1-(J15/H15) -> 0.10531859 | V15: =1-(L15/J15) -> 0.1177163 | W15: - | X15: - | Y15: - | Z15: - | AB15: =W15*X15*Y15/1000000 -> #VALUE!
A16: GUIELE004 | B16: - | D16: =LEN(C16) -> 0 | H16: 199990 | I16: 50.4 | J16: 179990 | K16: 46.5 | L16: 159990 | M16: 41.7 | N16: - | O16: - | P16: - | Q16: - | R16: - | S16: - | T16: - | U16: =1-(J16/H16) -> 0.100005 | V16: =1-(L16/J16) -> 0.11111728 | W16: 16 | X16: 105 | Y16: 45 | Z16: 7.6 | AB16: =W16*X16*Y16/1000000 -> 0.0756
A17: GUIELE002ZURDO | B17: - | D17: =LEN(C17) -> 0 | H17: 199990 | I17: 50.4 | J17: 179990 | K17: 46.5 | L17: 159990 | M17: 41.7 | N17: - | O17: - | P17: - | Q17: - | R17: - | S17: - | T17: - | U17: =1-(J17/H17) -> 0.100005 | V17: =1-(L17/J17) -> 0.11111728 | W17: 16 | X17: 105 | Y17: 45 | Z17: 7.6 | AB17: =W17*X17*Y17/1000000 -> 0.0756
A18: AMPLIFBAJO001 | B18: - | D18: =LEN(C18) -> 0 | H18: 59990 | I18: 47.4 | J18: 49990 | K18: 39.9 | L18: 44990 | M18: 34.9 | N18: - | O18: - | P18: - | Q18: - | R18: - | S18: - | T18: - | U18: =1-(J18/H18) -> 0.16669445 | V18: =1-(L18/J18) -> 0.10002 | W18: 13 | X18: 31 | Y18: 34 | Z18: 3.75 | AB18: =W18*X18*Y18/1000000 -> 0.013702
A19: CALIENTACAM2P | B19: - | H19: 59990 | I19: {=IF(OR(H19=0, H19=""), 0, 1 - ((((XLOOKUP($A19, 'datos de inventario'!$A:$A, 'datos de inventario'!$D:$D, 0) * 'datos de inventario'!$K$2) + (XLOOKUP($A19, 'datos de inventario'!$A:$A, 'datos de inventario'!$F:$F, 0) * 'datos de inventario'!$K$3 * 'datos de inventario'!$K$4)) * 1.19 + (H19 * 0.15) + XLOOKUP(MAX($Z19, (XLOOKUP($A19, 'datos de inventario'!$A:$A, 'datos de inventario'!$F:$F, 0) * 1000000 / 4000)) + 0.1, Tarifas!$A$2:$A$33, IF(H19 <= 9989, Tarifas!$B$2:$B$33, IF(H19 <= 19989, Tarifas!$C$2:$C$33, Tarifas!$D$2:$D$33)), "Peso excedido", 1)) / H19))} -> 0.46109277 | J19: 49990 | K19: {=IF(OR(J19=0, J19=""), 0, 1 - ((((XLOOKUP($A19, 'datos de inventario'!$A:$A, 'datos de inventario'!$D:$D, 0) * 'datos de inventario'!$K$2) + (XLOOKUP($A19, 'datos de inventario'!$A:$A, 'datos de inventario'!$F:$F, 0) * 'datos de inventario'!$K$3 * 'datos de inventario'!$K$4)) * 1.19 + (J19 * 0.15) + XLOOKUP(MAX($Z19, (XLOOKUP($A19, 'datos de inventario'!$A:$A, 'datos de inventario'!$F:$F, 0) * 1000000 / 4000)) + 0.1, Tarifas!$A$2:$A$33, IF(J19 <= 9989, Tarifas!$B$2:$B$33, IF(J19 <= 19989, Tarifas!$C$2:$C$33, Tarifas!$D$2:$D$33)), "Peso excedido", 1)) / J19))} -> 0.38329577 | L19: 44990 | M19: {=IF(OR(L19=0, L19=""), 0, 1 - ((((XLOOKUP($A19, 'datos de inventario'!$A:$A, 'datos de inventario'!$D:$D, 0) * 'datos de inventario'!$K$2) + (XLOOKUP($A19, 'datos de inventario'!$A:$A, 'datos de inventario'!$F:$F, 0) * 'datos de inventario'!$K$3 * 'datos de inventario'!$K$4)) * 1.19 + (L19 * 0.15) + XLOOKUP(MAX($Z19, (XLOOKUP($A19, 'datos de inventario'!$A:$A, 'datos de inventario'!$F:$F, 0) * 1000000 / 4000)) + 0.1, Tarifas!$A$2:$A$33, IF(L19 <= 9989, Tarifas!$B$2:$B$33, IF(L19 <= 19989, Tarifas!$C$2:$C$33, Tarifas!$D$2:$D$33)), "Peso excedido", 1)) / L19))} -> 0.33142822 | N19: - | O19: - | P19: - | Q19: - | R19: - | S19: - | T19: - | U19: =1-(J19/H19) -> 0.16669445 | V19: =1-(L19/J19) -> 0.10002 | W19: 14.5 | X19: 40 | Y19: 35 | Z19: 2.2 | AB19: =W19*X19*Y19/1000000 -> 0.0203
A20: CALIENTACAMKING | B20: - | H20: 149990 | I20: {=IF(OR(H20=0, H20=""), 0, 1 - ((((XLOOKUP($A20, 'datos de inventario'!$A:$A, 'datos de inventario'!$D:$D, 0) * 'datos de inventario'!$K$2) + (XLOOKUP($A20, 'datos de inventario'!$A:$A, 'datos de inventario'!$F:$F, 0) * 'datos de inventario'!$K$3 * 'datos de inventario'!$K$4)) * 1.19 + (H20 * 0.15) + XLOOKUP(MAX($Z20, (XLOOKUP($A20, 'datos de inventario'!$A:$A, 'datos de inventario'!$F:$F, 0) * 1000000 / 4000)) + 0.1, Tarifas!$A$2:$A$33, IF(H20 <= 9989, Tarifas!$B$2:$B$33, IF(H20 <= 19989, Tarifas!$C$2:$C$33, Tarifas!$D$2:$D$33)), "Peso excedido", 1)) / H20))} -> 0.6751267 | J20: 99990 | K20: {=IF(OR(J20=0, J20=""), 0, 1 - ((((XLOOKUP($A20, 'datos de inventario'!$A:$A, 'datos de inventario'!$D:$D, 0) * 'datos de inventario'!$K$2) + (XLOOKUP($A20, 'datos de inventario'!$A:$A, 'datos de inventario'!$F:$F, 0) * 'datos de inventario'!$K$3 * 'datos de inventario'!$K$4)) * 1.19 + (J20 * 0.15) + XLOOKUP(MAX($Z20, (XLOOKUP($A20, 'datos de inventario'!$A:$A, 'datos de inventario'!$F:$F, 0) * 1000000 / 4000)) + 0.1, Tarifas!$A$2:$A$33, IF(J20 <= 9989, Tarifas!$B$2:$B$33, IF(J20 <= 19989, Tarifas!$C$2:$C$33, Tarifas!$D$2:$D$33)), "Peso excedido", 1)) / J20))} -> 0.5876813 | L20: 89990 | M20: {=IF(OR(L20=0, L20=""), 0, 1 - ((((XLOOKUP($A20, 'datos de inventario'!$A:$A, 'datos de inventario'!$D:$D, 0) * 'datos de inventario'!$K$2) + (XLOOKUP($A20, 'datos de inventario'!$A:$A, 'datos de inventario'!$F:$F, 0) * 'datos de inventario'!$K$3 * 'datos de inventario'!$K$4)) * 1.19 + (L20 * 0.15) + XLOOKUP(MAX($Z20, (XLOOKUP($A20, 'datos de inventario'!$A:$A, 'datos de inventario'!$F:$F, 0) * 1000000 / 4000)) + 0.1, Tarifas!$A$2:$A$33, IF(L20 <= 9989, Tarifas!$B$2:$B$33, IF(L20 <= 19989, Tarifas!$C$2:$C$33, Tarifas!$D$2:$D$33)), "Peso excedido", 1)) / L20))} -> 0.55853154 | N20: - | O20: - | P20: - | Q20: - | R20: - | S20: - | T20: - | U20: =1-(J20/H20) -> 0.33335556 | V20: =1-(L20/J20) -> 0.10001 | W20: 19 | X20: 40 | Y20: 35 | Z20: 2.88 | AB20: =W20*X20*Y20/1000000 -> 0.0266
A21: KITGLUCOMETRO001 | B21: - | H21: 18990 | I21: {=IF(OR(H21=0, H21=""), 0, 1 - ((((XLOOKUP($A21, 'datos de inventario'!$A:$A, 'datos de inventario'!$D:$D, 0) * 'datos de inventario'!$K$2) + (XLOOKUP($A21, 'datos de inventario'!$A:$A, 'datos de inventario'!$F:$F, 0) * 'datos de inventario'!$K$3 * 'datos de inventario'!$K$4)) * 1.19 + (H21 * 0.15) + XLOOKUP(MAX($Z21, (XLOOKUP($A21, 'datos de inventario'!$A:$A, 'datos de inventario'!$F:$F, 0) * 1000000 / 4000)) + 0.1, Tarifas!$A$2:$A$33, IF(H21 <= 9989, Tarifas!$B$2:$B$33, IF(H21 <= 19989, Tarifas!$C$2:$C$33, Tarifas!$D$2:$D$33)), "Peso excedido", 1)) / H21))} -> 0.4103486 | J21: 16990 | K21: {=IF(OR(J21=0, J21=""), 0, 1 - ((((XLOOKUP($A21, 'datos de inventario'!$A:$A, 'datos de inventario'!$D:$D, 0) * 'datos de inventario'!$K$2) + (XLOOKUP($A21, 'datos de inventario'!$A:$A, 'datos de inventario'!$F:$F, 0) * 'datos de inventario'!$K$3 * 'datos de inventario'!$K$4)) * 1.19 + (J21 * 0.15) + XLOOKUP(MAX($Z21, (XLOOKUP($A21, 'datos de inventario'!$A:$A, 'datos de inventario'!$F:$F, 0) * 1000000 / 4000)) + 0.1, Tarifas!$A$2:$A$33, IF(J21 <= 9989, Tarifas!$B$2:$B$33, IF(J21 <= 19989, Tarifas!$C$2:$C$33, Tarifas!$D$2:$D$33)), "Peso excedido", 1)) / J21))} -> 0.35859447 | L21: 14990 | M21: {=IF(OR(L21=0, L21=""), 0, 1 - ((((XLOOKUP($A21, 'datos de inventario'!$A:$A, 'datos de inventario'!$D:$D, 0) * 'datos de inventario'!$K$2) + (XLOOKUP($A21, 'datos de inventario'!$A:$A, 'datos de inventario'!$F:$F, 0) * 'datos de inventario'!$K$3 * 'datos de inventario'!$K$4)) * 1.19 + (L21 * 0.15) + XLOOKUP(MAX($Z21, (XLOOKUP($A21, 'datos de inventario'!$A:$A, 'datos de inventario'!$F:$F, 0) * 1000000 / 4000)) + 0.1, Tarifas!$A$2:$A$33, IF(L21 <= 9989, Tarifas!$B$2:$B$33, IF(L21 <= 19989, Tarifas!$C$2:$C$33, Tarifas!$D$2:$D$33)), "Peso excedido", 1)) / L21))} -> 0.29303002 | N21: - | O21: - | P21: - | Q21: - | R21: - | S21: - | T21: - | U21: =1-(J21/H21) -> 0.10531859 | V21: =1-(L21/J21) -> 0.1177163 | W21: 4.5 | X21: 11.5 | Y21: 16 | Z21: 0.256 | AB21: =W21*X21*Y21/1000000 -> 0.000828
A22: PACKLANCETAS50U | B22: - | H22: 4990 | I22: {=IF(OR(H22=0, H22=""), 0, 1 - ((((XLOOKUP($A22, 'datos de inventario'!$A:$A, 'datos de inventario'!$D:$D, 0) * 'datos de inventario'!$K$2) + (XLOOKUP($A22, 'datos de inventario'!$A:$A, 'datos de inventario'!$F:$F, 0) * 'datos de inventario'!$K$3 * 'datos de inventario'!$K$4)) * 1.19 + (H22 * 0.15) + XLOOKUP(MAX($Z22, (XLOOKUP($A22, 'datos de inventario'!$A:$A, 'datos de inventario'!$F:$F, 0) * 1000000 / 4000)) + 0.1, Tarifas!$A$2:$A$33, IF(H22 <= 9989, Tarifas!$B$2:$B$33, IF(H22 <= 19989, Tarifas!$C$2:$C$33, Tarifas!$D$2:$D$33)), "Peso excedido", 1)) / H22))} -> 0.60585471 | J22: 3990 | K22: {=IF(OR(J22=0, J22=""), 0, 1 - ((((XLOOKUP($A22, 'datos de inventario'!$A:$A, 'datos de inventario'!$D:$D, 0) * 'datos de inventario'!$K$2) + (XLOOKUP($A22, 'datos de inventario'!$A:$A, 'datos de inventario'!$F:$F, 0) * 'datos de inventario'!$K$3 * 'datos de inventario'!$K$4)) * 1.19 + (J22 * 0.15) + XLOOKUP(MAX($Z22, (XLOOKUP($A22, 'datos de inventario'!$A:$A, 'datos de inventario'!$F:$F, 0) * 1000000 / 4000)) + 0.1, Tarifas!$A$2:$A$33, IF(J22 <= 9989, Tarifas!$B$2:$B$33, IF(J22 <= 19989, Tarifas!$C$2:$C$33, Tarifas!$D$2:$D$33)), "Peso excedido", 1)) / J22))} -> 0.54466541 | L22: 2990 | M22: {=IF(OR(L22=0, L22=""), 0, 1 - ((((XLOOKUP($A22, 'datos de inventario'!$A:$A, 'datos de inventario'!$D:$D, 0) * 'datos de inventario'!$K$2) + (XLOOKUP($A22, 'datos de inventario'!$A:$A, 'datos de inventario'!$F:$F, 0) * 'datos de inventario'!$K$3 * 'datos de inventario'!$K$4)) * 1.19 + (L22 * 0.15) + XLOOKUP(MAX($Z22, (XLOOKUP($A22, 'datos de inventario'!$A:$A, 'datos de inventario'!$F:$F, 0) * 1000000 / 4000)) + 0.1, Tarifas!$A$2:$A$33, IF(L22 <= 9989, Tarifas!$B$2:$B$33, IF(L22 <= 19989, Tarifas!$C$2:$C$33, Tarifas!$D$2:$D$33)), "Peso excedido", 1)) / L22))} -> 0.44254682 | N22: - | O22: - | P22: - | Q22: - | R22: - | S22: - | T22: - | U22: =1-(J22/H22) -> 0.2004008 | V22: =1-(L22/J22) -> 0.25062657 | W22: 4 | X22: 4 | Y22: 6 | Z22: 0.024 | AB22: =W22*X22*Y22/1000000 -> 9.6e-05
A23: PACKTIRAS50U | B23: - | H23: 12990 | I23: {=IF(OR(H23=0, H23=""), 0, 1 - ((((XLOOKUP($A23, 'datos de inventario'!$A:$A, 'datos de inventario'!$D:$D, 0) * 'datos de inventario'!$K$2) + (XLOOKUP($A23, 'datos de inventario'!$A:$A, 'datos de inventario'!$F:$F, 0) * 'datos de inventario'!$K$3 * 'datos de inventario'!$K$4)) * 1.19 + (H23 * 0.15) + XLOOKUP(MAX($Z23, (XLOOKUP($A23, 'datos de inventario'!$A:$A, 'datos de inventario'!$F:$F, 0) * 1000000 / 4000)) + 0.1, Tarifas!$A$2:$A$33, IF(H23 <= 9989, Tarifas!$B$2:$B$33, IF(H23 <= 19989, Tarifas!$C$2:$C$33, Tarifas!$D$2:$D$33)), "Peso excedido", 1)) / H23))} -> 0.53998749 | J23: 11990 | K23: {=IF(OR(J23=0, J23=""), 0, 1 - ((((XLOOKUP($A23, 'datos de inventario'!$A:$A, 'datos de inventario'!$D:$D, 0) * 'datos de inventario'!$K$2) + (XLOOKUP($A23, 'datos de inventario'!$A:$A, 'datos de inventario'!$F:$F, 0) * 'datos de inventario'!$K$3 * 'datos de inventario'!$K$4)) * 1.19 + (J23 * 0.15) + XLOOKUP(MAX($Z23, (XLOOKUP($A23, 'datos de inventario'!$A:$A, 'datos de inventario'!$F:$F, 0) * 1000000 / 4000)) + 0.1, Tarifas!$A$2:$A$33, IF(J23 <= 9989, Tarifas!$B$2:$B$33, IF(J23 <= 19989, Tarifas!$C$2:$C$33, Tarifas!$D$2:$D$33)), "Peso excedido", 1)) / J23))} -> 0.51413157 | L23: 10990 | M23: {=IF(OR(L23=0, L23=""), 0, 1 - ((((XLOOKUP($A23, 'datos de inventario'!$A:$A, 'datos de inventario'!$D:$D, 0) * 'datos de inventario'!$K$2) + (XLOOKUP($A23, 'datos de inventario'!$A:$A, 'datos de inventario'!$F:$F, 0) * 'datos de inventario'!$K$3 * 'datos de inventario'!$K$4)) * 1.19 + (L23 * 0.15) + XLOOKUP(MAX($Z23, (XLOOKUP($A23, 'datos de inventario'!$A:$A, 'datos de inventario'!$F:$F, 0) * 1000000 / 4000)) + 0.1, Tarifas!$A$2:$A$33, IF(L23 <= 9989, Tarifas!$B$2:$B$33, IF(L23 <= 19989, Tarifas!$C$2:$C$33, Tarifas!$D$2:$D$33)), "Peso excedido", 1)) / L23))} -> 0.48357029 | N23: - | O23: - | P23: - | Q23: - | R23: - | S23: - | T23: - | U23: =1-(J23/H23) -> 0.076982294 | V23: =1-(L23/J23) -> 0.083402836 | W23: 3.5 | X23: 4 | Y23: 6 | Z23: 0.026 | AB23: =W23*X23*Y23/1000000 -> 8.4e-05
A24: ACV004NEGRA | B24: - | H24: 26990 | I24: {=IF(OR(H24=0, H24=""), 0, 1 - ((((XLOOKUP($A24, 'datos de inventario'!$A:$A, 'datos de inventario'!$D:$D, 0) * 'datos de inventario'!$K$2) + (XLOOKUP($A24, 'datos de inventario'!$A:$A, 'datos de inventario'!$F:$F, 0) * 'datos de inventario'!$K$3 * 'datos de inventario'!$K$4)) * 1.19 + (H24 * 0.15) + XLOOKUP(MAX($Z24, (XLOOKUP($A24, 'datos de inventario'!$A:$A, 'datos de inventario'!$F:$F, 0) * 1000000 / 4000)) + 0.1, Tarifas!$A$2:$A$33, IF(H24 <= 9989, Tarifas!$B$2:$B$33, IF(H24 <= 19989, Tarifas!$C$2:$C$33, Tarifas!$D$2:$D$33)), "Peso excedido", 1)) / H24))} -> 0.38214881 | J24: 24990 | K24: {=IF(OR(J24=0, J24=""), 0, 1 - ((((XLOOKUP($A24, 'datos de inventario'!$A:$A, 'datos de inventario'!$D:$D, 0) * 'datos de inventario'!$K$2) + (XLOOKUP($A24, 'datos de inventario'!$A:$A, 'datos de inventario'!$F:$F, 0) * 'datos de inventario'!$K$3 * 'datos de inventario'!$K$4)) * 1.19 + (J24 * 0.15) + XLOOKUP(MAX($Z24, (XLOOKUP($A24, 'datos de inventario'!$A:$A, 'datos de inventario'!$F:$F, 0) * 1000000 / 4000)) + 0.1, Tarifas!$A$2:$A$33, IF(J24 <= 9989, Tarifas!$B$2:$B$33, IF(J24 <= 19989, Tarifas!$C$2:$C$33, Tarifas!$D$2:$D$33)), "Peso excedido", 1)) / J24))} -> 0.34470574 | L24: 18990 | M24: {=IF(OR(L24=0, L24=""), 0, 1 - ((((XLOOKUP($A24, 'datos de inventario'!$A:$A, 'datos de inventario'!$D:$D, 0) * 'datos de inventario'!$K$2) + (XLOOKUP($A24, 'datos de inventario'!$A:$A, 'datos de inventario'!$F:$F, 0) * 'datos de inventario'!$K$3 * 'datos de inventario'!$K$4)) * 1.19 + (L24 * 0.15) + XLOOKUP(MAX($Z24, (XLOOKUP($A24, 'datos de inventario'!$A:$A, 'datos de inventario'!$F:$F, 0) * 1000000 / 4000)) + 0.1, Tarifas!$A$2:$A$33, IF(L24 <= 9989, Tarifas!$B$2:$B$33, IF(L24 <= 19989, Tarifas!$C$2:$C$33, Tarifas!$D$2:$D$33)), "Peso excedido", 1)) / L24))} -> 0.357251 | N24: - | O24: - | P24: - | Q24: - | R24: - | S24: - | T24: - | U24: =1-(J24/H24) -> 0.074101519 | V24: =1-(L24/J24) -> 0.24009604 | W24: 17 | X24: 41 | Y24: 17 | Z24: 1.44 | AB24: =W24*X24*Y24/1000000 -> 0.011849
A25: PACKUKE003 | B25: - | H25: 44990 | I25: {=IF(OR(H25=0, H25=""), 0, 1 - ((((XLOOKUP($A25, 'datos de inventario'!$A:$A, 'datos de inventario'!$D:$D, 0) * 'datos de inventario'!$K$2) + (XLOOKUP($A25, 'datos de inventario'!$A:$A, 'datos de inventario'!$F:$F, 0) * 'datos de inventario'!$K$3 * 'datos de inventario'!$K$4)) * 1.19 + (H25 * 0.15) + XLOOKUP(MAX($Z25, (XLOOKUP($A25, 'datos de inventario'!$A:$A, 'datos de inventario'!$F:$F, 0) * 1000000 / 4000)) + 0.1, Tarifas!$A$2:$A$33, IF(H25 <= 9989, Tarifas!$B$2:$B$33, IF(H25 <= 19989, Tarifas!$C$2:$C$33, Tarifas!$D$2:$D$33)), "Peso excedido", 1)) / H25))} -> 0.45490287 | J25: 39990 | K25: {=IF(OR(J25=0, J25=""), 0, 1 - ((((XLOOKUP($A25, 'datos de inventario'!$A:$A, 'datos de inventario'!$D:$D, 0) * 'datos de inventario'!$K$2) + (XLOOKUP($A25, 'datos de inventario'!$A:$A, 'datos de inventario'!$F:$F, 0) * 'datos de inventario'!$K$3 * 'datos de inventario'!$K$4)) * 1.19 + (J25 * 0.15) + XLOOKUP(MAX($Z25, (XLOOKUP($A25, 'datos de inventario'!$A:$A, 'datos de inventario'!$F:$F, 0) * 1000000 / 4000)) + 0.1, Tarifas!$A$2:$A$33, IF(J25 <= 9989, Tarifas!$B$2:$B$33, IF(J25 <= 19989, Tarifas!$C$2:$C$33, Tarifas!$D$2:$D$33)), "Peso excedido", 1)) / J25))} -> 0.40550338 | L25: 34990 | M25: {=IF(OR(L25=0, L25=""), 0, 1 - ((((XLOOKUP($A25, 'datos de inventario'!$A:$A, 'datos de inventario'!$D:$D, 0) * 'datos de inventario'!$K$2) + (XLOOKUP($A25, 'datos de inventario'!$A:$A, 'datos de inventario'!$F:$F, 0) * 'datos de inventario'!$K$3 * 'datos de inventario'!$K$4)) * 1.19 + (L25 * 0.15) + XLOOKUP(MAX($Z25, (XLOOKUP($A25, 'datos de inventario'!$A:$A, 'datos de inventario'!$F:$F, 0) * 1000000 / 4000)) + 0.1, Tarifas!$A$2:$A$33, IF(L25 <= 9989, Tarifas!$B$2:$B$33, IF(L25 <= 19989, Tarifas!$C$2:$C$33, Tarifas!$D$2:$D$33)), "Peso excedido", 1)) / L25))} -> 0.34198571 | N25: - | O25: - | P25: - | Q25: - | R25: - | S25: - | T25: - | U25: =1-(J25/H25) -> 0.11113581 | V25: =1-(L25/J25) -> 0.12503126 | W25: 9 | X25: 22.5 | Y25: 58 | Z25: 0.8 | AB25: =W25*X25*Y25/1000000 -> 0.011745
A26: SILLARUEDA001 | B26: - | H26: 119990 | I26: {=IF(OR(H26=0, H26=""), 0, 1 - ((((XLOOKUP($A26, 'datos de inventario'!$A:$A, 'datos de inventario'!$D:$D, 0) * 'datos de inventario'!$K$2) + (XLOOKUP($A26, 'datos de inventario'!$A:$A, 'datos de inventario'!$F:$F, 0) * 'datos de inventario'!$K$3 * 'datos de inventario'!$K$4)) * 1.19 + (H26 * 0.15) + XLOOKUP(MAX($Z26, (XLOOKUP($A26, 'datos de inventario'!$A:$A, 'datos de inventario'!$F:$F, 0) * 1000000 / 4000)) + 0.1, Tarifas!$A$2:$A$33, IF(H26 <= 9989, Tarifas!$B$2:$B$33, IF(H26 <= 19989, Tarifas!$C$2:$C$33, Tarifas!$D$2:$D$33)), "Peso excedido", 1)) / H26))} -> 0.25039941 | J26: 109990 | K26: {=IF(OR(J26=0, J26=""), 0, 1 - ((((XLOOKUP($A26, 'datos de inventario'!$A:$A, 'datos de inventario'!$D:$D, 0) * 'datos de inventario'!$K$2) + (XLOOKUP($A26, 'datos de inventario'!$A:$A, 'datos de inventario'!$F:$F, 0) * 'datos de inventario'!$K$3 * 'datos de inventario'!$K$4)) * 1.19 + (J26 * 0.15) + XLOOKUP(MAX($Z26, (XLOOKUP($A26, 'datos de inventario'!$A:$A, 'datos de inventario'!$F:$F, 0) * 1000000 / 4000)) + 0.1, Tarifas!$A$2:$A$33, IF(J26 <= 9989, Tarifas!$B$2:$B$33, IF(J26 <= 19989, Tarifas!$C$2:$C$33, Tarifas!$D$2:$D$33)), "Peso excedido", 1)) / J26))} -> 0.19588531 | L26: 99990 | M26: {=IF(OR(L26=0, L26=""), 0, 1 - ((((XLOOKUP($A26, 'datos de inventario'!$A:$A, 'datos de inventario'!$D:$D, 0) * 'datos de inventario'!$K$2) + (XLOOKUP($A26, 'datos de inventario'!$A:$A, 'datos de inventario'!$F:$F, 0) * 'datos de inventario'!$K$3 * 'datos de inventario'!$K$4)) * 1.19 + (L26 * 0.15) + XLOOKUP(MAX($Z26, (XLOOKUP($A26, 'datos de inventario'!$A:$A, 'datos de inventario'!$F:$F, 0) * 1000000 / 4000)) + 0.1, Tarifas!$A$2:$A$33, IF(L26 <= 9989, Tarifas!$B$2:$B$33, IF(L26 <= 19989, Tarifas!$C$2:$C$33, Tarifas!$D$2:$D$33)), "Peso excedido", 1)) / L26))} -> 0.1304673 | N26: - | O26: - | P26: - | Q26: - | R26: - | S26: - | T26: - | U26: =1-(J26/H26) -> 0.083340278 | V26: =1-(L26/J26) -> 0.090917356 | W26: 25 | X26: 87 | Y26: 88 | Z26: 14.04 | AB26: =W26*X26*Y26/1000000 -> 0.1914
A27: CUCHILLOSANTOKU002 | B27: - | H27: 29990 | I27: {=IF(OR(H27=0, H27=""), 0, 1 - ((((XLOOKUP($A27, 'datos de inventario'!$A:$A, 'datos de inventario'!$D:$D, 0) * 'datos de inventario'!$K$2) + (XLOOKUP($A27, 'datos de inventario'!$A:$A, 'datos de inventario'!$F:$F, 0) * 'datos de inventario'!$K$3 * 'datos de inventario'!$K$4)) * 1.19 + (H27 * 0.15) + XLOOKUP(MAX($Z27, (XLOOKUP($A27, 'datos de inventario'!$A:$A, 'datos de inventario'!$F:$F, 0) * 1000000 / 4000)) + 0.1, Tarifas!$A$2:$A$33, IF(H27 <= 9989, Tarifas!$B$2:$B$33, IF(H27 <= 19989, Tarifas!$C$2:$C$33, Tarifas!$D$2:$D$33)), "Peso excedido", 1)) / H27))} -> 0.54379652 | J27: 24990 | K27: {=IF(OR(J27=0, J27=""), 0, 1 - ((((XLOOKUP($A27, 'datos de inventario'!$A:$A, 'datos de inventario'!$D:$D, 0) * 'datos de inventario'!$K$2) + (XLOOKUP($A27, 'datos de inventario'!$A:$A, 'datos de inventario'!$F:$F, 0) * 'datos de inventario'!$K$3 * 'datos de inventario'!$K$4)) * 1.19 + (J27 * 0.15) + XLOOKUP(MAX($Z27, (XLOOKUP($A27, 'datos de inventario'!$A:$A, 'datos de inventario'!$F:$F, 0) * 1000000 / 4000)) + 0.1, Tarifas!$A$2:$A$33, IF(J27 <= 9989, Tarifas!$B$2:$B$33, IF(J27 <= 19989, Tarifas!$C$2:$C$33, Tarifas!$D$2:$D$33)), "Peso excedido", 1)) / J27))} -> 0.48253131 | L27: 18990 | M27: {=IF(OR(L27=0, L27=""), 0, 1 - ((((XLOOKUP($A27, 'datos de inventario'!$A:$A, 'datos de inventario'!$D:$D, 0) * 'datos de inventario'!$K$2) + (XLOOKUP($A27, 'datos de inventario'!$A:$A, 'datos de inventario'!$F:$F, 0) * 'datos de inventario'!$K$3 * 'datos de inventario'!$K$4)) * 1.19 + (L27 * 0.15) + XLOOKUP(MAX($Z27, (XLOOKUP($A27, 'datos de inventario'!$A:$A, 'datos de inventario'!$F:$F, 0) * 1000000 / 4000)) + 0.1, Tarifas!$A$2:$A$33, IF(L27 <= 9989, Tarifas!$B$2:$B$33, IF(L27 <= 19989, Tarifas!$C$2:$C$33, Tarifas!$D$2:$D$33)), "Peso excedido", 1)) / L27))} -> 0.4828045 | N27: - | O27: - | P27: - | Q27: - | R27: - | S27: - | T27: - | U27: =1-(J27/H27) -> 0.16672224 | V27: =1-(L27/J27) -> 0.24009604 | W27: 8 | X27: 38 | Y27: 3 | Z27: 0.41 | AB27: =W27*X27*Y27/1000000 -> 0.000912
A28: MATYOG003NEG | B28: - | H28: 18990 | I28: {=IF(OR(H28=0, H28=""), 0, 1 - ((((XLOOKUP($A28, 'datos de inventario'!$A:$A, 'datos de inventario'!$D:$D, 0) * 'datos de inventario'!$K$2) + (XLOOKUP($A28, 'datos de inventario'!$A:$A, 'datos de inventario'!$F:$F, 0) * 'datos de inventario'!$K$3 * 'datos de inventario'!$K$4)) * 1.19 + (H28 * 0.15) + XLOOKUP(MAX($Z29, (XLOOKUP($A28, 'datos de inventario'!$A:$A, 'datos de inventario'!$F:$F, 0) * 1000000 / 4000)) + 0.1, Tarifas!$A$2:$A$33, IF(H28 <= 9989, Tarifas!$B$2:$B$33, IF(H28 <= 19989, Tarifas!$C$2:$C$33, Tarifas!$D$2:$D$33)), "Peso excedido", 1)) / H28))} -> 0.42901132 | J28: 17990 | K28: {=IF(OR(J28=0, J28=""), 0, 1 - ((((XLOOKUP($A28, 'datos de inventario'!$A:$A, 'datos de inventario'!$D:$D, 0) * 'datos de inventario'!$K$2) + (XLOOKUP($A28, 'datos de inventario'!$A:$A, 'datos de inventario'!$F:$F, 0) * 'datos de inventario'!$K$3 * 'datos de inventario'!$K$4)) * 1.19 + (J28 * 0.15) + XLOOKUP(MAX($Z29, (XLOOKUP($A28, 'datos de inventario'!$A:$A, 'datos de inventario'!$F:$F, 0) * 1000000 / 4000)) + 0.1, Tarifas!$A$2:$A$33, IF(J28 <= 9989, Tarifas!$B$2:$B$33, IF(J28 <= 19989, Tarifas!$C$2:$C$33, Tarifas!$D$2:$D$33)), "Peso excedido", 1)) / J28))} -> 0.40561006 | L28: 16990 | M28: {=IF(OR(L28=0, L28=""), 0, 1 - ((((XLOOKUP($A28, 'datos de inventario'!$A:$A, 'datos de inventario'!$D:$D, 0) * 'datos de inventario'!$K$2) + (XLOOKUP($A28, 'datos de inventario'!$A:$A, 'datos de inventario'!$F:$F, 0) * 'datos de inventario'!$K$3 * 'datos de inventario'!$K$4)) * 1.19 + (L28 * 0.15) + XLOOKUP(MAX($Z29, (XLOOKUP($A28, 'datos de inventario'!$A:$A, 'datos de inventario'!$F:$F, 0) * 1000000 / 4000)) + 0.1, Tarifas!$A$2:$A$33, IF(L28 <= 9989, Tarifas!$B$2:$B$33, IF(L28 <= 19989, Tarifas!$C$2:$C$33, Tarifas!$D$2:$D$33)), "Peso excedido", 1)) / L28))} -> 0.37945409 | N28: - | O28: - | P28: - | Q28: - | R28: - | S28: - | T28: - | U28: =1-(J28/H28) -> 0.052659294 | V28: =1-(L28/J28) -> 0.055586437 | W28: 15 | X28: 15 | Y28: 61 | Z28: 1.048 | AB28: =W28*X28*Y28/1000000 -> 0.013725
A29: CUCHI002 | W29: 8 | X29: 39 | Y29: 3 | Z29: 0.38 | AB29: =W29*X29*Y29/1000000 -> 0.000936
A30: MATYOGNBR002ROS | B30: - | H30: 19980 | I30: {=IF(OR(H30=0, H30=""), 0, 1 - ((((XLOOKUP($A30, 'datos de inventario'!$A:$A, 'datos de inventario'!$D:$D, 0) * 'datos de inventario'!$K$2) + (XLOOKUP($A30, 'datos de inventario'!$A:$A, 'datos de inventario'!$F:$F, 0) * 'datos de inventario'!$K$3 * 'datos de inventario'!$K$4)) * 1.19 + (H30 * 0.15) + XLOOKUP(MAX($Z30, (XLOOKUP($A30, 'datos de inventario'!$A:$A, 'datos de inventario'!$F:$F, 0) * 1000000 / 4000)) + 0.1, Tarifas!$A$2:$A$33, IF(H30 <= 9989, Tarifas!$B$2:$B$33, IF(H30 <= 19989, Tarifas!$C$2:$C$33, Tarifas!$D$2:$D$33)), "Peso excedido", 1)) / H30))} -> 0.40135798 | J30: 18990 | K30: {=IF(OR(J30=0, J30=""), 0, 1 - ((((XLOOKUP($A30, 'datos de inventario'!$A:$A, 'datos de inventario'!$D:$D, 0) * 'datos de inventario'!$K$2) + (XLOOKUP($A30, 'datos de inventario'!$A:$A, 'datos de inventario'!$F:$F, 0) * 'datos de inventario'!$K$3 * 'datos de inventario'!$K$4)) * 1.19 + (J30 * 0.15) + XLOOKUP(MAX($Z30, (XLOOKUP($A30, 'datos de inventario'!$A:$A, 'datos de inventario'!$F:$F, 0) * 1000000 / 4000)) + 0.1, Tarifas!$A$2:$A$33, IF(J30 <= 9989, Tarifas!$B$2:$B$33, IF(J30 <= 19989, Tarifas!$C$2:$C$33, Tarifas!$D$2:$D$33)), "Peso excedido", 1)) / J30))} -> 0.37796906 | L30: 17990 | M30: {=IF(OR(L30=0, L30=""), 0, 1 - ((((XLOOKUP($A30, 'datos de inventario'!$A:$A, 'datos de inventario'!$D:$D, 0) * 'datos de inventario'!$K$2) + (XLOOKUP($A30, 'datos de inventario'!$A:$A, 'datos de inventario'!$F:$F, 0) * 'datos de inventario'!$K$3 * 'datos de inventario'!$K$4)) * 1.19 + (L30 * 0.15) + XLOOKUP(MAX($Z30, (XLOOKUP($A30, 'datos de inventario'!$A:$A, 'datos de inventario'!$F:$F, 0) * 1000000 / 4000)) + 0.1, Tarifas!$A$2:$A$33, IF(L30 <= 9989, Tarifas!$B$2:$B$33, IF(L30 <= 19989, Tarifas!$C$2:$C$33, Tarifas!$D$2:$D$33)), "Peso excedido", 1)) / L30))} -> 0.35173054 | N30: - | O30: - | P30: - | Q30: - | R30: - | S30: - | T30: - | U30: =1-(J30/H30) -> 0.04954955 | V30: =1-(L30/J30) -> 0.052659294 | W30: 20 | X30: 20 | Y30: 64 | Z30: 0.988 | AB30: =W30*X30*Y30/1000000 -> 0.0256
A31: LAMPARAMES002NEG | B31: - | H31: 22990 | I31: {=IF(OR(H31=0, H31=""), 0, 1 - ((((XLOOKUP($A31, 'datos de inventario'!$A:$A, 'datos de inventario'!$D:$D, 0) * 'datos de inventario'!$K$2) + (XLOOKUP($A31, 'datos de inventario'!$A:$A, 'datos de inventario'!$F:$F, 0) * 'datos de inventario'!$K$3 * 'datos de inventario'!$K$4)) * 1.19 + (H31 * 0.15) + XLOOKUP(MAX($Z31, (XLOOKUP($A31, 'datos de inventario'!$A:$A, 'datos de inventario'!$F:$F, 0) * 1000000 / 4000)) + 0.1, Tarifas!$A$2:$A$33, IF(H31 <= 9989, Tarifas!$B$2:$B$33, IF(H31 <= 19989, Tarifas!$C$2:$C$33, Tarifas!$D$2:$D$33)), "Peso excedido", 1)) / H31))} -> 0.31075544 | J31: 19980 | K31: {=IF(OR(J31=0, J31=""), 0, 1 - ((((XLOOKUP($A31, 'datos de inventario'!$A:$A, 'datos de inventario'!$D:$D, 0) * 'datos de inventario'!$K$2) + (XLOOKUP($A31, 'datos de inventario'!$A:$A, 'datos de inventario'!$F:$F, 0) * 'datos de inventario'!$K$3 * 'datos de inventario'!$K$4)) * 1.19 + (J31 * 0.15) + XLOOKUP(MAX($Z31, (XLOOKUP($A31, 'datos de inventario'!$A:$A, 'datos de inventario'!$F:$F, 0) * 1000000 / 4000)) + 0.1, Tarifas!$A$2:$A$33, IF(J31 <= 9989, Tarifas!$B$2:$B$33, IF(J31 <= 19989, Tarifas!$C$2:$C$33, Tarifas!$D$2:$D$33)), "Peso excedido", 1)) / J31))} -> 0.3401285 | L31: 17990 | M31: {=IF(OR(L31=0, L31=""), 0, 1 - ((((XLOOKUP($A31, 'datos de inventario'!$A:$A, 'datos de inventario'!$D:$D, 0) * 'datos de inventario'!$K$2) + (XLOOKUP($A31, 'datos de inventario'!$A:$A, 'datos de inventario'!$F:$F, 0) * 'datos de inventario'!$K$3 * 'datos de inventario'!$K$4)) * 1.19 + (L31 * 0.15) + XLOOKUP(MAX($Z31, (XLOOKUP($A31, 'datos de inventario'!$A:$A, 'datos de inventario'!$F:$F, 0) * 1000000 / 4000)) + 0.1, Tarifas!$A$2:$A$33, IF(L31 <= 9989, Tarifas!$B$2:$B$33, IF(L31 <= 19989, Tarifas!$C$2:$C$33, Tarifas!$D$2:$D$33)), "Peso excedido", 1)) / L31))} -> 0.28372804 | N31: - | O31: - | P31: - | Q31: - | R31: - | S31: - | T31: - | U31: =1-(J31/H31) -> 0.13092649 | V31: =1-(L31/J31) -> 0.0995996 | W31: 13 | X31: 42 | Y31: 5 | Z31: 0.66 | AB31: =W31*X31*Y31/1000000 -> 0.00273
A32: TIRASNASALE30U001 | B32: - | H32: 18990 | I32: {=IF(OR(H32=0, H32=""), 0, 1 - ((((XLOOKUP($A32, 'datos de inventario'!$A:$A, 'datos de inventario'!$D:$D, 0) * 'datos de inventario'!$K$2) + (XLOOKUP($A32, 'datos de inventario'!$A:$A, 'datos de inventario'!$F:$F, 0) * 'datos de inventario'!$K$3 * 'datos de inventario'!$K$4)) * 1.19 + (H32 * 0.15) + XLOOKUP(MAX($Z32, (XLOOKUP($A32, 'datos de inventario'!$A:$A, 'datos de inventario'!$F:$F, 0) * 1000000 / 4000)) + 0.1, Tarifas!$A$2:$A$33, IF(H32 <= 9989, Tarifas!$B$2:$B$33, IF(H32 <= 19989, Tarifas!$C$2:$C$33, Tarifas!$D$2:$D$33)), "Peso excedido", 1)) / H32))} -> 0.62924302 | J32: 14990 | K32: {=IF(OR(J32=0, J32=""), 0, 1 - ((((XLOOKUP($A32, 'datos de inventario'!$A:$A, 'datos de inventario'!$D:$D, 0) * 'datos de inventario'!$K$2) + (XLOOKUP($A32, 'datos de inventario'!$A:$A, 'datos de inventario'!$F:$F, 0) * 'datos de inventario'!$K$3 * 'datos de inventario'!$K$4)) * 1.19 + (J32 * 0.15) + XLOOKUP(MAX($Z32, (XLOOKUP($A32, 'datos de inventario'!$A:$A, 'datos de inventario'!$F:$F, 0) * 1000000 / 4000)) + 0.1, Tarifas!$A$2:$A$33, IF(J32 <= 9989, Tarifas!$B$2:$B$33, IF(J32 <= 19989, Tarifas!$C$2:$C$33, Tarifas!$D$2:$D$33)), "Peso excedido", 1)) / J32))} -> 0.57033522 | L32: 12990 | M32: {=IF(OR(L32=0, L32=""), 0, 1 - ((((XLOOKUP($A32, 'datos de inventario'!$A:$A, 'datos de inventario'!$D:$D, 0) * 'datos de inventario'!$K$2) + (XLOOKUP($A32, 'datos de inventario'!$A:$A, 'datos de inventario'!$F:$F, 0) * 'datos de inventario'!$K$3 * 'datos de inventario'!$K$4)) * 1.19 + (L32 * 0.15) + XLOOKUP(MAX($Z32, (XLOOKUP($A32, 'datos de inventario'!$A:$A, 'datos de inventario'!$F:$F, 0) * 1000000 / 4000)) + 0.1, Tarifas!$A$2:$A$33, IF(L32 <= 9989, Tarifas!$B$2:$B$33, IF(L32 <= 19989, Tarifas!$C$2:$C$33, Tarifas!$D$2:$D$33)), "Peso excedido", 1)) / L32))} -> 0.52727675 | N32: - | O32: - | P32: - | Q32: - | R32: - | S32: - | T32: - | U32: =1-(J32/H32) -> 0.21063718 | V32: =1-(L32/J32) -> 0.13342228 | W32: 2 | X32: 7 | Y32: 10 | Z32: 0.032 | AB32: =W32*X32*Y32/1000000 -> 0.00014
A33: BOTASCOMPRESION001 | B33: - | H33: 89990 | I33: {=IF(OR(H33=0, H33=""), 0, 1 - ((((XLOOKUP($A33, 'datos de inventario'!$A:$A, 'datos de inventario'!$D:$D, 0) * 'datos de inventario'!$K$2) + (XLOOKUP($A33, 'datos de inventario'!$A:$A, 'datos de inventario'!$F:$F, 0) * 'datos de inventario'!$K$3 * 'datos de inventario'!$K$4)) * 1.19 + (H33 * 0.15) + XLOOKUP(MAX($Z33, (XLOOKUP($A33, 'datos de inventario'!$A:$A, 'datos de inventario'!$F:$F, 0) * 1000000 / 4000)) + 0.1, Tarifas!$A$2:$A$33, IF(H33 <= 9989, Tarifas!$B$2:$B$33, IF(H33 <= 19989, Tarifas!$C$2:$C$33, Tarifas!$D$2:$D$33)), "Peso excedido", 1)) / H33))} -> 0.4546344 | J33: 79990 | K33: {=IF(OR(J33=0, J33=""), 0, 1 - ((((XLOOKUP($A33, 'datos de inventario'!$A:$A, 'datos de inventario'!$D:$D, 0) * 'datos de inventario'!$K$2) + (XLOOKUP($A33, 'datos de inventario'!$A:$A, 'datos de inventario'!$F:$F, 0) * 'datos de inventario'!$K$3 * 'datos de inventario'!$K$4)) * 1.19 + (J33 * 0.15) + XLOOKUP(MAX($Z33, (XLOOKUP($A33, 'datos de inventario'!$A:$A, 'datos de inventario'!$F:$F, 0) * 1000000 / 4000)) + 0.1, Tarifas!$A$2:$A$33, IF(J33 <= 9989, Tarifas!$B$2:$B$33, IF(J33 <= 19989, Tarifas!$C$2:$C$33, Tarifas!$D$2:$D$33)), "Peso excedido", 1)) / J33))} -> 0.40520752 | L33: 69990 | M33: {=IF(OR(L33=0, L33=""), 0, 1 - ((((XLOOKUP($A33, 'datos de inventario'!$A:$A, 'datos de inventario'!$D:$D, 0) * 'datos de inventario'!$K$2) + (XLOOKUP($A33, 'datos de inventario'!$A:$A, 'datos de inventario'!$F:$F, 0) * 'datos de inventario'!$K$3 * 'datos de inventario'!$K$4)) * 1.19 + (L33 * 0.15) + XLOOKUP(MAX($Z33, (XLOOKUP($A33, 'datos de inventario'!$A:$A, 'datos de inventario'!$F:$F, 0) * 1000000 / 4000)) + 0.1, Tarifas!$A$2:$A$33, IF(L33 <= 9989, Tarifas!$B$2:$B$33, IF(L33 <= 19989, Tarifas!$C$2:$C$33, Tarifas!$D$2:$D$33)), "Peso excedido", 1)) / L33))} -> 0.34165666 | N33: - | O33: - | P33: - | Q33: - | R33: - | S33: - | T33: - | U33: =1-(J33/H33) -> 0.11112346 | V33: =1-(L33/J33) -> 0.12501563 | W33: 7.5 | X33: 36 | Y33: 28 | Z33: 1.8 | AB33: =W33*X33*Y33/1000000 -> 0.00756
A34: DISCOGOMA5KG | B34: - | H34: 18990 | I34: {=IF(OR(H34=0, H34=""), 0, 1 - ((((XLOOKUP($A34, 'datos de inventario'!$A:$A, 'datos de inventario'!$D:$D, 0) * 'datos de inventario'!$K$2) + (XLOOKUP($A34, 'datos de inventario'!$A:$A, 'datos de inventario'!$F:$F, 0) * 'datos de inventario'!$K$3 * 'datos de inventario'!$K$4)) * 1.19 + (H34 * 0.15) + XLOOKUP(MAX($Z34, (XLOOKUP($A34, 'datos de inventario'!$A:$A, 'datos de inventario'!$F:$F, 0) * 1000000 / 4000)) + 0.1, Tarifas!$A$2:$A$33, IF(H34 <= 9989, Tarifas!$B$2:$B$33, IF(H34 <= 19989, Tarifas!$C$2:$C$33, Tarifas!$D$2:$D$33)), "Peso excedido", 1)) / H34))} -> 0.39643227 | J34: 16990 | K34: {=IF(OR(J34=0, J34=""), 0, 1 - ((((XLOOKUP($A34, 'datos de inventario'!$A:$A, 'datos de inventario'!$D:$D, 0) * 'datos de inventario'!$K$2) + (XLOOKUP($A34, 'datos de inventario'!$A:$A, 'datos de inventario'!$F:$F, 0) * 'datos de inventario'!$K$3 * 'datos de inventario'!$K$4)) * 1.19 + (J34 * 0.15) + XLOOKUP(MAX($Z34, (XLOOKUP($A34, 'datos de inventario'!$A:$A, 'datos de inventario'!$F:$F, 0) * 1000000 / 4000)) + 0.1, Tarifas!$A$2:$A$33, IF(J34 <= 9989, Tarifas!$B$2:$B$33, IF(J34 <= 19989, Tarifas!$C$2:$C$33, Tarifas!$D$2:$D$33)), "Peso excedido", 1)) / J34))} -> 0.34303995 | L34: 14990 | M34: {=IF(OR(L34=0, L34=""), 0, 1 - ((((XLOOKUP($A34, 'datos de inventario'!$A:$A, 'datos de inventario'!$D:$D, 0) * 'datos de inventario'!$K$2) + (XLOOKUP($A34, 'datos de inventario'!$A:$A, 'datos de inventario'!$F:$F, 0) * 'datos de inventario'!$K$3 * 'datos de inventario'!$K$4)) * 1.19 + (L34 * 0.15) + XLOOKUP(MAX($Z34, (XLOOKUP($A34, 'datos de inventario'!$A:$A, 'datos de inventario'!$F:$F, 0) * 1000000 / 4000)) + 0.1, Tarifas!$A$2:$A$33, IF(L34 <= 9989, Tarifas!$B$2:$B$33, IF(L34 <= 19989, Tarifas!$C$2:$C$33, Tarifas!$D$2:$D$33)), "Peso excedido", 1)) / L34))} -> 0.27540018 | N34: - | O34: - | P34: - | Q34: - | R34: - | S34: - | T34: - | U34: =1-(J34/H34) -> 0.10531859 | V34: =1-(L34/J34) -> 0.1177163 | W34: 3 | X34: 47 | Y34: 47 | Z34: 5.4 | AB34: =W34*X34*Y34/1000000 -> 0.006627
A35: DISCOGOMA10KG | B35: - | H35: 44990 | I35: {=IF(OR(H35=0, H35=""), 0, 1 - ((((XLOOKUP($A35, 'datos de inventario'!$A:$A, 'datos de inventario'!$D:$D, 0) * 'datos de inventario'!$K$2) + (XLOOKUP($A35, 'datos de inventario'!$A:$A, 'datos de inventario'!$F:$F, 0) * 'datos de inventario'!$K$3 * 'datos de inventario'!$K$4)) * 1.19 + (H35 * 0.15) + XLOOKUP(MAX($Z35, (XLOOKUP($A35, 'datos de inventario'!$A:$A, 'datos de inventario'!$F:$F, 0) * 1000000 / 4000)) + 0.1, Tarifas!$A$2:$A$33, IF(H35 <= 9989, Tarifas!$B$2:$B$33, IF(H35 <= 19989, Tarifas!$C$2:$C$33, Tarifas!$D$2:$D$33)), "Peso excedido", 1)) / H35))} -> 0.39426174 | J35: 39990 | K35: {=IF(OR(J35=0, J35=""), 0, 1 - ((((XLOOKUP($A35, 'datos de inventario'!$A:$A, 'datos de inventario'!$D:$D, 0) * 'datos de inventario'!$K$2) + (XLOOKUP($A35, 'datos de inventario'!$A:$A, 'datos de inventario'!$F:$F, 0) * 'datos de inventario'!$K$3 * 'datos de inventario'!$K$4)) * 1.19 + (J35 * 0.15) + XLOOKUP(MAX($Z35, (XLOOKUP($A35, 'datos de inventario'!$A:$A, 'datos de inventario'!$F:$F, 0) * 1000000 / 4000)) + 0.1, Tarifas!$A$2:$A$33, IF(J35 <= 9989, Tarifas!$B$2:$B$33, IF(J35 <= 19989, Tarifas!$C$2:$C$33, Tarifas!$D$2:$D$33)), "Peso excedido", 1)) / J35))} -> 0.33728021 | L35: 37990 | M35: {=IF(OR(L35=0, L35=""), 0, 1 - ((((XLOOKUP($A35, 'datos de inventario'!$A:$A, 'datos de inventario'!$D:$D, 0) * 'datos de inventario'!$K$2) + (XLOOKUP($A35, 'datos de inventario'!$A:$A, 'datos de inventario'!$F:$F, 0) * 'datos de inventario'!$K$3 * 'datos de inventario'!$K$4)) * 1.19 + (L35 * 0.15) + XLOOKUP(MAX($Z35, (XLOOKUP($A35, 'datos de inventario'!$A:$A, 'datos de inventario'!$F:$F, 0) * 1000000 / 4000)) + 0.1, Tarifas!$A$2:$A$33, IF(L35 <= 9989, Tarifas!$B$2:$B$33, IF(L35 <= 19989, Tarifas!$C$2:$C$33, Tarifas!$D$2:$D$33)), "Peso excedido", 1)) / L35))} -> 0.31028785 | N35: - | O35: - | P35: - | Q35: - | R35: - | S35: - | T35: - | U35: =1-(J35/H35) -> 0.11113581 | V35: =1-(L35/J35) -> 0.050012503 | W35: 4 | X35: 47 | Y35: 47 | Z35: 10.3 | AB35: =W35*X35*Y35/1000000 -> 0.008836
A36: DISCOGOMA15KG | B36: - | H36: 59990 | I36: {=IF(OR(H36=0, H36=""), 0, 1 - ((((XLOOKUP($A36, 'datos de inventario'!$A:$A, 'datos de inventario'!$D:$D, 0) * 'datos de inventario'!$K$2) + (XLOOKUP($A36, 'datos de inventario'!$A:$A, 'datos de inventario'!$F:$F, 0) * 'datos de inventario'!$K$3 * 'datos de inventario'!$K$4)) * 1.19 + (H36 * 0.15) + XLOOKUP(MAX($Z36, (XLOOKUP($A36, 'datos de inventario'!$A:$A, 'datos de inventario'!$F:$F, 0) * 1000000 / 4000)) + 0.1, Tarifas!$A$2:$A$33, IF(H36 <= 9989, Tarifas!$B$2:$B$33, IF(H36 <= 19989, Tarifas!$C$2:$C$33, Tarifas!$D$2:$D$33)), "Peso excedido", 1)) / H36))} -> 0.39160785 | J36: 54990 | K36: {=IF(OR(J36=0, J36=""), 0, 1 - ((((XLOOKUP($A36, 'datos de inventario'!$A:$A, 'datos de inventario'!$D:$D, 0) * 'datos de inventario'!$K$2) + (XLOOKUP($A36, 'datos de inventario'!$A:$A, 'datos de inventario'!$F:$F, 0) * 'datos de inventario'!$K$3 * 'datos de inventario'!$K$4)) * 1.19 + (J36 * 0.15) + XLOOKUP(MAX($Z36, (XLOOKUP($A36, 'datos de inventario'!$A:$A, 'datos de inventario'!$F:$F, 0) * 1000000 / 4000)) + 0.1, Tarifas!$A$2:$A$33, IF(J36 <= 9989, Tarifas!$B$2:$B$33, IF(J36 <= 19989, Tarifas!$C$2:$C$33, Tarifas!$D$2:$D$33)), "Peso excedido", 1)) / J36))} -> 0.34992826 | L36: 49990 | M36: {=IF(OR(L36=0, L36=""), 0, 1 - ((((XLOOKUP($A36, 'datos de inventario'!$A:$A, 'datos de inventario'!$D:$D, 0) * 'datos de inventario'!$K$2) + (XLOOKUP($A36, 'datos de inventario'!$A:$A, 'datos de inventario'!$F:$F, 0) * 'datos de inventario'!$K$3 * 'datos de inventario'!$K$4)) * 1.19 + (L36 * 0.15) + XLOOKUP(MAX($Z36, (XLOOKUP($A36, 'datos de inventario'!$A:$A, 'datos de inventario'!$F:$F, 0) * 1000000 / 4000)) + 0.1, Tarifas!$A$2:$A$33, IF(L36 <= 9989, Tarifas!$B$2:$B$33, IF(L36 <= 19989, Tarifas!$C$2:$C$33, Tarifas!$D$2:$D$33)), "Peso excedido", 1)) / L36))} -> 0.29991108 | N36: - | O36: - | P36: - | Q36: - | R36: - | S36: - | T36: - | U36: =1-(J36/H36) -> 0.083347225 | V36: =1-(L36/J36) -> 0.090925623 | W36: 6 | X36: 47 | Y36: 47 | Z36: 15.5 | AB36: =W36*X36*Y36/1000000 -> 0.013254
A37: DISCOGOMA20KG | B37: - | H37: 74990 | I37: {=IF(OR(H37=0, H37=""), 0, 1 - ((((XLOOKUP($A37, 'datos de inventario'!$A:$A, 'datos de inventario'!$D:$D, 0) * 'datos de inventario'!$K$2) + (XLOOKUP($A37, 'datos de inventario'!$A:$A, 'datos de inventario'!$F:$F, 0) * 'datos de inventario'!$K$3 * 'datos de inventario'!$K$4)) * 1.19 + (H37 * 0.15) + XLOOKUP(MAX($Z37, (XLOOKUP($A37, 'datos de inventario'!$A:$A, 'datos de inventario'!$F:$F, 0) * 1000000 / 4000)) + 0.1, Tarifas!$A$2:$A$33, IF(H37 <= 9989, Tarifas!$B$2:$B$33, IF(H37 <= 19989, Tarifas!$C$2:$C$33, Tarifas!$D$2:$D$33)), "Peso excedido", 1)) / H37))} -> 0.38000933 | J37: 69990 | K37: {=IF(OR(J37=0, J37=""), 0, 1 - ((((XLOOKUP($A37, 'datos de inventario'!$A:$A, 'datos de inventario'!$D:$D, 0) * 'datos de inventario'!$K$2) + (XLOOKUP($A37, 'datos de inventario'!$A:$A, 'datos de inventario'!$F:$F, 0) * 'datos de inventario'!$K$3 * 'datos de inventario'!$K$4)) * 1.19 + (J37 * 0.15) + XLOOKUP(MAX($Z37, (XLOOKUP($A37, 'datos de inventario'!$A:$A, 'datos de inventario'!$F:$F, 0) * 1000000 / 4000)) + 0.1, Tarifas!$A$2:$A$33, IF(J37 <= 9989, Tarifas!$B$2:$B$33, IF(J37 <= 19989, Tarifas!$C$2:$C$33, Tarifas!$D$2:$D$33)), "Peso excedido", 1)) / J37))} -> 0.34643377 | L37: 64990 | M37: {=IF(OR(L37=0, L37=""), 0, 1 - ((((XLOOKUP($A37, 'datos de inventario'!$A:$A, 'datos de inventario'!$D:$D, 0) * 'datos de inventario'!$K$2) + (XLOOKUP($A37, 'datos de inventario'!$A:$A, 'datos de inventario'!$F:$F, 0) * 'datos de inventario'!$K$3 * 'datos de inventario'!$K$4)) * 1.19 + (L37 * 0.15) + XLOOKUP(MAX($Z37, (XLOOKUP($A37, 'datos de inventario'!$A:$A, 'datos de inventario'!$F:$F, 0) * 1000000 / 4000)) + 0.1, Tarifas!$A$2:$A$33, IF(L37 <= 9989, Tarifas!$B$2:$B$33, IF(L37 <= 19989, Tarifas!$C$2:$C$33, Tarifas!$D$2:$D$33)), "Peso excedido", 1)) / L37))} -> 0.30769194 | N37: - | O37: - | P37: - | Q37: - | R37: - | S37: - | T37: - | U37: =1-(J37/H37) -> 0.066675557 | V37: =1-(L37/J37) -> 0.071438777 | W37: 7 | X37: 47 | Y37: 47 | Z37: 20.6 | AB37: =W37*X37*Y37/1000000 -> 0.015463
A38: MAN30KGCRO | B38: - | H38: 99990 | I38: {=IF(OR(H38=0, H38=""), 0, 1 - ((((XLOOKUP($A38, 'datos de inventario'!$A:$A, 'datos de inventario'!$D:$D, 0) * 'datos de inventario'!$K$2) + (XLOOKUP($A38, 'datos de inventario'!$A:$A, 'datos de inventario'!$F:$F, 0) * 'datos de inventario'!$K$3 * 'datos de inventario'!$K$4)) * 1.19 + (H38 * 0.15) + XLOOKUP(MAX($Z38, (XLOOKUP($A38, 'datos de inventario'!$A:$A, 'datos de inventario'!$F:$F, 0) * 1000000 / 4000)) + 0.1, Tarifas!$A$2:$A$33, IF(H38 <= 9989, Tarifas!$B$2:$B$33, IF(H38 <= 19989, Tarifas!$C$2:$C$33, Tarifas!$D$2:$D$33)), "Peso excedido", 1)) / H38))} -> 0.35002158 | J38: 89990 | K38: {=IF(OR(J38=0, J38=""), 0, 1 - ((((XLOOKUP($A38, 'datos de inventario'!$A:$A, 'datos de inventario'!$D:$D, 0) * 'datos de inventario'!$K$2) + (XLOOKUP($A38, 'datos de inventario'!$A:$A, 'datos de inventario'!$F:$F, 0) * 'datos de inventario'!$K$3 * 'datos de inventario'!$K$4)) * 1.19 + (J38 * 0.15) + XLOOKUP(MAX($Z38, (XLOOKUP($A38, 'datos de inventario'!$A:$A, 'datos de inventario'!$F:$F, 0) * 1000000 / 4000)) + 0.1, Tarifas!$A$2:$A$33, IF(J38 <= 9989, Tarifas!$B$2:$B$33, IF(J38 <= 19989, Tarifas!$C$2:$C$33, Tarifas!$D$2:$D$33)), "Peso excedido", 1)) / J38))} -> 0.29446225 | L38: 84990 | M38: {=IF(OR(L38=0, L38=""), 0, 1 - ((((XLOOKUP($A38, 'datos de inventario'!$A:$A, 'datos de inventario'!$D:$D, 0) * 'datos de inventario'!$K$2) + (XLOOKUP($A38, 'datos de inventario'!$A:$A, 'datos de inventario'!$F:$F, 0) * 'datos de inventario'!$K$3 * 'datos de inventario'!$K$4)) * 1.19 + (L38 * 0.15) + XLOOKUP(MAX($Z38, (XLOOKUP($A38, 'datos de inventario'!$A:$A, 'datos de inventario'!$F:$F, 0) * 1000000 / 4000)) + 0.1, Tarifas!$A$2:$A$33, IF(L38 <= 9989, Tarifas!$B$2:$B$33, IF(L38 <= 19989, Tarifas!$C$2:$C$33, Tarifas!$D$2:$D$33)), "Peso excedido", 1)) / L38))} -> 0.26177971 | N38: - | O38: - | P38: - | Q38: - | R38: - | S38: - | T38: - | U38: =1-(J38/H38) -> 0.10001 | V38: =1-(L38/J38) -> 0.055561729 | W38: 32 | X38: 41.5 | Y38: 18 | Z38: 30 | AB38: =W38*X38*Y38/1000000 -> 0.023904
A39: HEXBAR23KG | B39: - | H39: 129990 | I39: {=IF(OR(H39=0, H39=""), 0, 1 - ((((XLOOKUP($A39, 'datos de inventario'!$A:$A, 'datos de inventario'!$D:$D, 0) * 'datos de inventario'!$K$2) + (XLOOKUP($A39, 'datos de inventario'!$A:$A, 'datos de inventario'!$F:$F, 0) * 'datos de inventario'!$K$3 * 'datos de inventario'!$K$4)) * 1.19 + (H39 * 0.15) + XLOOKUP(MAX($Z39, (XLOOKUP($A39, 'datos de inventario'!$A:$A, 'datos de inventario'!$F:$F, 0) * 1000000 / 4000)) + 0.1, Tarifas!$A$2:$A$33, IF(H39 <= 9989, Tarifas!$B$2:$B$33, IF(H39 <= 19989, Tarifas!$C$2:$C$33, Tarifas!$D$2:$D$33)), "Peso excedido", 1)) / H39))} -> 0.48185789 | J39: 119990 | K39: {=IF(OR(J39=0, J39=""), 0, 1 - ((((XLOOKUP($A39, 'datos de inventario'!$A:$A, 'datos de inventario'!$D:$D, 0) * 'datos de inventario'!$K$2) + (XLOOKUP($A39, 'datos de inventario'!$A:$A, 'datos de inventario'!$F:$F, 0) * 'datos de inventario'!$K$3 * 'datos de inventario'!$K$4)) * 1.19 + (J39 * 0.15) + XLOOKUP(MAX($Z39, (XLOOKUP($A39, 'datos de inventario'!$A:$A, 'datos de inventario'!$F:$F, 0) * 1000000 / 4000)) + 0.1, Tarifas!$A$2:$A$33, IF(J39 <= 9989, Tarifas!$B$2:$B$33, IF(J39 <= 19989, Tarifas!$C$2:$C$33, Tarifas!$D$2:$D$33)), "Peso excedido", 1)) / J39))} -> 0.45117683 | L39: 109990 | M39: {=IF(OR(L39=0, L39=""), 0, 1 - ((((XLOOKUP($A39, 'datos de inventario'!$A:$A, 'datos de inventario'!$D:$D, 0) * 'datos de inventario'!$K$2) + (XLOOKUP($A39, 'datos de inventario'!$A:$A, 'datos de inventario'!$F:$F, 0) * 'datos de inventario'!$K$3 * 'datos de inventario'!$K$4)) * 1.19 + (L39 * 0.15) + XLOOKUP(MAX($Z39, (XLOOKUP($A39, 'datos de inventario'!$A:$A, 'datos de inventario'!$F:$F, 0) * 1000000 / 4000)) + 0.1, Tarifas!$A$2:$A$33, IF(L39 <= 9989, Tarifas!$B$2:$B$33, IF(L39 <= 19989, Tarifas!$C$2:$C$33, Tarifas!$D$2:$D$33)), "Peso excedido", 1)) / L39))} -> 0.41491688 | N39: - | O39: - | P39: - | Q39: - | R39: - | S39: - | T39: - | U39: =1-(J39/H39) -> 0.076928995 | V39: =1-(L39/J39) -> 0.083340278 | W39: 57 | X39: 142 | Y39: 10 | Z39: 22.3 | AB39: =W39*X39*Y39/1000000 -> 0.08094
A40: TECLM004 | W40: 11.5 | X40: 102 | Y40: 30 | Z40: 4.154 | AB40: =W40*X40*Y40/1000000 -> 0.03519
A41: STRAPGYM001 | B41: Straps Correas Levantamiento De Pesas Gym | C41: Lifting Straps Muñequeras Overfit Gym Correas Levantamientos | D41: =LEN(C41) -> 60 | E41: Lifting Straps Muñequeras Overfit Gym Correas Para Levantamientos De Pesas Y Barras | H41: 7990 | I41: {=IF(OR(H41=0, H41=""), 0, 1 - ((((XLOOKUP($A41, 'datos de inventario'!$A:$A, 'datos de inventario'!$D:$D, 0) * 'datos de inventario'!$K$2) + (XLOOKUP($A41, 'datos de inventario'!$A:$A, 'datos de inventario'!$F:$F, 0) * 'datos de inventario'!$K$3 * 'datos de inventario'!$K$4)) * 1.19 + (H41 * 0.15) + XLOOKUP(MAX($Z41, (XLOOKUP($A41, 'datos de inventario'!$A:$A, 'datos de inventario'!$F:$F, 0) * 1000000 / 4000)) + 0.1, Tarifas!$A$2:$A$33, IF(H41 <= 9989, Tarifas!$B$2:$B$33, IF(H41 <= 19989, Tarifas!$C$2:$C$33, Tarifas!$D$2:$D$33)), "Peso excedido", 1)) / H41))} -> 0.45037165 | J41: 6990 | K41: {=IF(OR(J41=0, J41=""), 0, 1 - ((((XLOOKUP($A41, 'datos de inventario'!$A:$A, 'datos de inventario'!$D:$D, 0) * 'datos de inventario'!$K$2) + (XLOOKUP($A41, 'datos de inventario'!$A:$A, 'datos de inventario'!$F:$F, 0) * 'datos de inventario'!$K$3 * 'datos de inventario'!$K$4)) * 1.19 + (J41 * 0.15) + XLOOKUP(MAX($Z41, (XLOOKUP($A41, 'datos de inventario'!$A:$A, 'datos de inventario'!$F:$F, 0) * 1000000 / 4000)) + 0.1, Tarifas!$A$2:$A$33, IF(J41 <= 9989, Tarifas!$B$2:$B$33, IF(J41 <= 19989, Tarifas!$C$2:$C$33, Tarifas!$D$2:$D$33)), "Peso excedido", 1)) / J41))} -> 0.39320021 | L41: 5990 | M41: {=IF(OR(L41=0, L41=""), 0, 1 - ((((XLOOKUP($A41, 'datos de inventario'!$A:$A, 'datos de inventario'!$D:$D, 0) * 'datos de inventario'!$K$2) + (XLOOKUP($A41, 'datos de inventario'!$A:$A, 'datos de inventario'!$F:$F, 0) * 'datos de inventario'!$K$3 * 'datos de inventario'!$K$4)) * 1.19 + (L41 * 0.15) + XLOOKUP(MAX($Z41, (XLOOKUP($A41, 'datos de inventario'!$A:$A, 'datos de inventario'!$F:$F, 0) * 1000000 / 4000)) + 0.1, Tarifas!$A$2:$A$33, IF(L41 <= 9989, Tarifas!$B$2:$B$33, IF(L41 <= 19989, Tarifas!$C$2:$C$33, Tarifas!$D$2:$D$33)), "Peso excedido", 1)) / L41))} -> 0.31693982 | N41: Vestuario y CalzadoRopa DeportivaOtrosMunequera Levantamiento de Pesas | AB41: =W41*X41*Y41/1000000 -> 0
...

Sheet Revisión velocidades
A1: SKU | B1: Producto | C1: Margen Marzo | D1: Gasto publicidad mes actual Acos | E1: Precio de venta calculado | F1: Velocidad inicial semanal | G1: Velocidad madura semanal | H1: Fehca de llegada | I1: Días de rotación | J1: =VLOOKUP($A$1,'Cruce APP Velocidad ultimas 5 s'!$A$1:$L$1,6,0) -> W13 | K1: =VLOOKUP($A$1,'Cruce APP Velocidad ultimas 5 s'!$A$1:$L$1,7,0) -> W14 | L1: =VLOOKUP($A$1,'Cruce APP Velocidad ultimas 5 s'!$A$1:$L$1,8,0) -> W15 | M1: =VLOOKUP($A$1,'Cruce APP Velocidad ultimas 5 s'!$A$1:$L$1,9,0) -> W16 | N1: =VLOOKUP($A$1,'Cruce APP Velocidad ultimas 5 s'!$A$1:$L$1,10,0) -> W17 | O1: stock | P1: Nota | Q1: Palancas | R1: Palancas | S1: Palancas | T1: Palancas
A2: TROTAELEC002 | B2: =VLOOKUP(A2,'Cruce APP Velocidad ultimas 5 s'!A:B,2,0) -> Trotadora 2 Hp Overfit Caminadora Electrica Plegable 12 Km/h | C2: =VLOOKUP(A2,'App dashboard año actual'!A:I,9,0) -> 33,7 | D2: =VLOOKUP(A2,'App dashboard año actual'!A:K,11,0)/VLOOKUP(A2,'App dashboard año actual'!A:N,3,0) -> 0.049486849 | E2: =IFERROR(VLOOKUP(A2,'App dashboard año actual'!A:E,3,0)/VLOOKUP(A2,'App dashboard año actual'!A:E,5,0),"Sin ventas") -> 200887.12 | F2: 1.2 | G2: 4.7 | H2: 46065 | I2: =TODAY()-H2 -> 68 | J2: =VLOOKUP(A2,'Cruce APP Velocidad ultimas 5 s'!A:H,6,0) -> 0 | K2: =VLOOKUP(A2,'Cruce APP Velocidad ultimas 5 s'!A:H,7,0) -> 0 | L2: =VLOOKUP(A2,'Cruce APP Velocidad ultimas 5 s'!A:H,8,0) -> 0 | M2: =VLOOKUP(A2,'Cruce APP Velocidad ultimas 5 s'!A:I,9,0) -> 0 | N2: =VLOOKUP(A2,'Cruce APP Velocidad ultimas 5 s'!A:J,10,0) -> 0 | P2: Listo
A3: TROTAELEC003 | B3: =VLOOKUP(A3,'Cruce APP Velocidad ultimas 5 s'!A:B,2,0) -> Trotadora 1.5 Hp Overfit Caminadora Electrica Plegable 8km/h | C3: =VLOOKUP(A3,'App dashboard año actual'!A:I,9,0) -> 31,84 | D3: =VLOOKUP(A3,'App dashboard año actual'!A:K,11,0)/VLOOKUP(A3,'App dashboard año actual'!A:N,3,0) -> 0.051539011 | E3: =IFERROR(VLOOKUP(A3,'App dashboard año actual'!A:E,3,0)/VLOOKUP(A3,'App dashboard año actual'!A:E,5,0),"Sin ventas") -> 152721.42 | F3: 1.2 | G3: 4.7 | H3: 46065 | I3: =TODAY()-H3 -> 68 | J3: =VLOOKUP(A3,'Cruce APP Velocidad ultimas 5 s'!A:H,6,0) -> 4 | K3: =VLOOKUP(A3,'Cruce APP Velocidad ultimas 5 s'!A:H,7,0) -> 10 | L3: =VLOOKUP(A3,'Cruce APP Velocidad ultimas 5 s'!A:H,8,0) -> 3 | M3: =VLOOKUP(A3,'Cruce APP Velocidad ultimas 5 s'!A:I,9,0) -> 4 | N3: =VLOOKUP(A3,'Cruce APP Velocidad ultimas 5 s'!A:J,10,0) -> 0 | P3: Listo
A4: FUNGUI002 | B4: =VLOOKUP(A4,'Cruce APP Velocidad ultimas 5 s'!A:B,2,0) -> Funda Para Guitarra 41 Pulgadas Ibrah Bolso De Transporte | C4: =VLOOKUP(A4,'App dashboard año actual'!A:I,9,0) -> 33,17 | D4: =VLOOKUP(A4,'App dashboard año actual'!A:K,11,0)/VLOOKUP(A4,'App dashboard año actual'!A:N,3,0) -> 0.048755039 | E4: =IFERROR(VLOOKUP(A4,'App dashboard año actual'!A:E,3,0)/VLOOKUP(A4,'App dashboard año actual'!A:E,5,0),"Sin ventas") -> 19952.766 | F4: 1.2 | G4: 4.7 | H4: 46071 | I4: =TODAY()-H4 -> 62 | J4: =VLOOKUP(A4,'Cruce APP Velocidad ultimas 5 s'!A:H,6,0) -> 18 | K4: =VLOOKUP(A4,'Cruce APP Velocidad ultimas 5 s'!A:H,7,0) -> 18 | L4: =VLOOKUP(A4,'Cruce APP Velocidad ultimas 5 s'!A:H,8,0) -> 38 | M4: =VLOOKUP(A4,'Cruce APP Velocidad ultimas 5 s'!A:I,9,0) -> 31 | N4: =VLOOKUP(A4,'Cruce APP Velocidad ultimas 5 s'!A:J,10,0) -> 2 | P4: Listo
A5: BANCOGYM001 | B5: =VLOOKUP(A5,'Cruce APP Velocidad ultimas 5 s'!A:B,2,0) -> Banco Reclinable Gym Multifuncional Overfit Press Ajustable | C5: =VLOOKUP(A5,'App dashboard año actual'!A:I,9,0) -> 45,36 | D5: =VLOOKUP(A5,'App dashboard año actual'!A:K,11,0)/VLOOKUP(A5,'App dashboard año actual'!A:N,3,0) -> 0.041474249 | E5: =IFERROR(VLOOKUP(A5,'App dashboard año actual'!A:E,3,0)/VLOOKUP(A5,'App dashboard año actual'!A:E,5,0),"Sin ventas") -> 94850.787 | F5: 1.2 | G5: 4.7 | H5: 46071 | I5: =TODAY()-H5 -> 62 | J5: =VLOOKUP(A5,'Cruce APP Velocidad ultimas 5 s'!A:H,6,0) -> 1 | K5: =VLOOKUP(A5,'Cruce APP Velocidad ultimas 5 s'!A:H,7,0) -> 15 | L5: =VLOOKUP(A5,'Cruce APP Velocidad ultimas 5 s'!A:H,8,0) -> 0 | M5: =VLOOKUP(A5,'Cruce APP Velocidad ultimas 5 s'!A:I,9,0) -> 3 | N5: =VLOOKUP(A5,'Cruce APP Velocidad ultimas 5 s'!A:J,10,0) -> 1 | P5: Listo
A6: GUIACU003 | B6: =VLOOKUP(A6,'Cruce APP Velocidad ultimas 5 s'!A:B,2,0) -> Guitarra Acustica Cutaway Ibrah Music 38 plgds + accesorios | C6: =VLOOKUP(A6,'App dashboard año actual'!A:I,9,0) -> 38,2 | D6: =VLOOKUP(A6,'App dashboard año actual'!A:K,11,0)/VLOOKUP(A6,'App dashboard año actual'!A:N,3,0) -> 0.057097127 | E6: =IFERROR(VLOOKUP(A6,'App dashboard año actual'!A:E,3,0)/VLOOKUP(A6,'App dashboard año actual'!A:E,5,0),"Sin ventas") -> 61012.202 | F6: 1.2 | G6: 4.7 | H6: 46071 | I6: =TODAY()-H6 -> 62 | J6: =VLOOKUP(A6,'Cruce APP Velocidad ultimas 5 s'!A:H,6,0) -> 31 | K6: =VLOOKUP(A6,'Cruce APP Velocidad ultimas 5 s'!A:H,7,0) -> 57 | L6: =VLOOKUP(A6,'Cruce APP Velocidad ultimas 5 s'!A:H,8,0) -> 45 | M6: =VLOOKUP(A6,'Cruce APP Velocidad ultimas 5 s'!A:I,9,0) -> 27 | N6: =VLOOKUP(A6,'Cruce APP Velocidad ultimas 5 s'!A:J,10,0) -> 1 | P6: Listo
A7: MONCURGAMER27 | B7: =VLOOKUP(A7,'Cruce APP Velocidad ultimas 5 s'!A:B,2,0) -> Monitor Gamer Curvo 27" Hosser Fhd 165Hz Gaming Freesync 1ms | C7: =VLOOKUP(A7,'App dashboard año actual'!A:I,9,0) -> 29,97 | D7: =VLOOKUP(A7,'App dashboard año actual'!A:K,11,0)/VLOOKUP(A7,'App dashboard año actual'!A:N,3,0) -> 0.031482226 | E7: =IFERROR(VLOOKUP(A7,'App dashboard año actual'!A:E,3,0)/VLOOKUP(A7,'App dashboard año actual'!A:E,5,0),"Sin ventas") -> 138104.79 | F7: 1.2 | G7: 4.7 | H7: 46071 | I7: =TODAY()-H7 -> 62 | J7: =VLOOKUP(A7,'Cruce APP Velocidad ultimas 5 s'!A:H,6,0) -> 4 | K7: =VLOOKUP(A7,'Cruce APP Velocidad ultimas 5 s'!A:H,7,0) -> 35 | L7: =VLOOKUP(A7,'Cruce APP Velocidad ultimas 5 s'!A:H,8,0) -> 7 | M7: =VLOOKUP(A7,'Cruce APP Velocidad ultimas 5 s'!A:I,9,0) -> 3 | N7: =VLOOKUP(A7,'Cruce APP Velocidad ultimas 5 s'!A:J,10,0) -> 0 | P7: Listo
A8: MONCURGAMER34 | B8: =VLOOKUP(A8,'Cruce APP Velocidad ultimas 5 s'!A:B,2,0) -> Monitor PC Gamer Curvo 34" Hosser FHD 165 Hz Gaming 1 ms | C8: =VLOOKUP(A8,'App dashboard año actual'!A:I,9,0) -> 37,02 | D8: =VLOOKUP(A8,'App dashboard año actual'!A:K,11,0)/VLOOKUP(A8,'App dashboard año actual'!A:N,3,0) -> 0.031977702 | E8: =IFERROR(VLOOKUP(A8,'App dashboard año actual'!A:E,3,0)/VLOOKUP(A8,'App dashboard año actual'!A:E,5,0),"Sin ventas") -> 277019.42 | F8: 1.2 | G8: 4.7 | H8: 46071 | I8: =TODAY()-H8 -> 62 | J8: =VLOOKUP(A8,'Cruce APP Velocidad ultimas 5 s'!A:H,6,0) -> 7 | K8: =VLOOKUP(A8,'Cruce APP Velocidad ultimas 5 s'!A:H,7,0) -> 7 | L8: =VLOOKUP(A8,'Cruce APP Velocidad ultimas 5 s'!A:H,8,0) -> 5 | M8: =VLOOKUP(A8,'Cruce APP Velocidad ultimas 5 s'!A:I,9,0) -> 0 | N8: =VLOOKUP(A8,'Cruce APP Velocidad ultimas 5 s'!A:J,10,0) -> 0 | P8: Listo
A9: BATERIAELE001 | B9: =VLOOKUP(A9,'Cruce APP Velocidad ultimas 5 s'!A:B,2,0) -> Bateria Electrica Ibrah Music | C9: =VLOOKUP(A9,'App dashboard año actual'!A:I,9,0) -> 40,36 | D9: =VLOOKUP(A9,'App dashboard año actual'!A:K,11,0)/VLOOKUP(A9,'App dashboard año actual'!A:N,3,0) -> 0.03232644 | E9: =IFERROR(VLOOKUP(A9,'App dashboard año actual'!A:E,3,0)/VLOOKUP(A9,'App dashboard año actual'!A:E,5,0),"Sin ventas") -> 391412.51 | F9: 1.2 | G9: 4.7 | H9: 46072 | I9: =TODAY()-H9 -> 61 | J9: =VLOOKUP(A9,'Cruce APP Velocidad ultimas 5 s'!A:H,6,0) -> 1 | K9: =VLOOKUP(A9,'Cruce APP Velocidad ultimas 5 s'!A:H,7,0) -> 18 | L9: =VLOOKUP(A9,'Cruce APP Velocidad ultimas 5 s'!A:H,8,0) -> 4 | M9: =VLOOKUP(A9,'Cruce APP Velocidad ultimas 5 s'!A:I,9,0) -> 7 | N9: =VLOOKUP(A9,'Cruce APP Velocidad ultimas 5 s'!A:J,10,0) -> 1 | P9: Listo
A10: GUIELEFV004NEG | B10: =VLOOKUP(A10,'Cruce APP Velocidad ultimas 5 s'!A:B,2,0) -> Guitarra Electrica Flying V 39" Ibrah Music Amplificador 20W | C10: =VLOOKUP(A10,'App dashboard año actual'!A:I,9,0) -> 30,22 | D10: =VLOOKUP(A10,'App dashboard año actual'!A:K,11,0)/VLOOKUP(A10,'App dashboard año actual'!A:N,3,0) -> 0.21495704 | E10: =IFERROR(VLOOKUP(A10,'App dashboard año actual'!A:E,3,0)/VLOOKUP(A10,'App dashboard año actual'!A:E,5,0),"Sin ventas") -> 229644.33 | F10: 1.2 | G10: 4.7 | H10: 46072 | I10: =TODAY()-H10 -> 61 | J10: =VLOOKUP(A10,'Cruce APP Velocidad ultimas 5 s'!A:H,6,0) -> 1 | K10: =VLOOKUP(A10,'Cruce APP Velocidad ultimas 5 s'!A:H,7,0) -> 0 | L10: =VLOOKUP(A10,'Cruce APP Velocidad ultimas 5 s'!A:H,8,0) -> 2 | M10: =VLOOKUP(A10,'Cruce APP Velocidad ultimas 5 s'!A:I,9,0) -> 1 | N10: =VLOOKUP(A10,'Cruce APP Velocidad ultimas 5 s'!A:J,10,0) -> 0 | P10: revisar en reunion de el miercoles con el equipo
